Workbook
Name ASM_PP: '[1]Pencapaian ASM ALL Q2 '!$C$24:$Q$27
Name ASM_RO: '[1]Pencapaian ASM ALL Q2 '!$C$15:$K$18
Name ASM_SV: '[1]Pencapaian ASM ALL Q2 '!$C$6:$N$9
Name PP_JABAR: #REF!

Sheet Rekap Insentif Sales Copy
B2: PENCAPAIAN AREA JAWA BARAT-1 | P2: Output Insentif dijadikan PDF
B3: NAMA CABANG | C3: SALES VALUE | D3: PRODUCT FOCUS | F3: EFFECTIVE CALL | G3: NEW OPEN OUTLET | H3: ACTIVE OUTLET | I3: ITEM PER OUTLET | J3: PRODUCT DISPLAY | K3: SALES CONTRACT | L3: CO-BRANDING | M3: JOIN EVENT ACTIVITY | N3: TOTAL INSENTIF | P3: NAMA CABANG | Q3: ID | R3: SALESMAN | S3: TYPE SALES | T3: SALES VALUE | V3: PRODUCT FOCUS | Y3: EFFECTIVE CALL | AA3: NEW OPEN OUTLET | AC3: ACTIVE OUTLET | AE3: ITEM PER OUTLET | AG3: PRODUCT DISPLAY | AI3: SALES CONTRACT | AK3: CO-BRANDING | AM3: JOIN EVENT ACTIVITY | AO3: TOTAL | AP3: AR PERFORM | AT3: TOTAL INSENTIF DITERIMA | AU3: SALESMAN | AV3: DRIVER / HELPER
D4: VOLUME | E4: RO | T4: PENCAPAIAN | U4: INSENTIF | V4: VOLUME | W4: RO | X4: INSENTIF | Y4: PENCAPAIAN | Z4: INSENTIF | AA4: PENCAPAIAN | AB4: INSENTIF | AC4: PENCAPAIAN | AD4: INSENTIF | AE4: PENCAPAIAN | AF4: INSENTIF | AG4: PENCAPAIAN | AH4: INSENTIF | AI4: PENCAPAIAN | AJ4: INSENTIF | AK4: PENCAPAIAN | AL4: INSENTIF | AM4: PENCAPAIAN | AN4: INSENTIF | AP4: OVERDUE | AQ4: PENGURANG INSENTIF | AR4: BAD DEBT | AS4: PENGURANG INSENTIF
B5: CABANG BANDUNG | C5: ='Pencapaian Sales Value'!G28 -> 0.88311921 | D5: ='Pencapaian Product Focus'!H28 -> 0.92620649 | E5: ='Pencapaian Product Focus'!L28 -> 0.98741673 | F5: ='Pencapaian Effective Call'!G28 -> 0.93160483 | G5: ='Pencapaian New Open Outlet'!G28 -> 0.27102804 | H5: ='Pencapaian Active Outlet'!G28 -> 0.94270668 | I5: ='Pencapaian Item per Outlet'!G28 -> 0.79537525 | J5: ='Pencapaian Product Display'!G28 -> 0.89090909 | K5: ='Pencapaian Sales Contract'!G28 -> 0 | L5: ='Pencapaian Co-Branding'!G28 -> 0 | M5: ='Pencapaian Join Event Activity'!G28 -> 1 | N5: =AO28 -> 12948500 | P5: BANDUNG | Q5: BDG-SLS-GT-001 | R5: Wawan Kurniawan | S5: 3 Orang | T5: ='Pencapaian Sales Value'!G5 -> 1.0094593 | U5: ='Pencapaian Sales Value'!I5 -> 600000 | V5: ='Pencapaian Product Focus'!H5 -> 0.90859586 | W5: ='Pencapaian Product Focus'!L5 -> 1 | X5: ='Pencapaian Product Focus'!N5 -> 210000 | Y5: ='Pencapaian Effective Call'!G5 -> 1.0814815 | Z5: ='Pencapaian Effective Call'!I5 -> 180000 | AA5: ='Pencapaian New Open Outlet'!G5 -> 0.5 | AB5: ='Pencapaian New Open Outlet'!I5 -> 0 | AC5: ='Pencapaian Active Outlet'!G5 -> 1.0350877 | AD5: ='Pencapaian Active Outlet'!I5 -> 0 | AE5: ='Pencapaian Item per Outlet'!G5 -> 0.90248734 | AF5: ='Pencapaian Item per Outlet'!I5 -> 135000 | AG5: ='Pencapaian Product Display'!G5 -> 0 | AH5: ='Pencapaian Product Display'!I5 -> 0 | AI5: ='Pencapaian Sales Contract'!G5 -> 0 | AJ5: ='Pencapaian Sales Contract'!I5 -> 0 | AK5: ='Pencapaian Co-Branding'!G5 -> 0 | AL5: ='Pencapaian Co-Branding'!I5 -> 0 | AM5: ='Pencapaian Join Event Activity'!G5 -> 0 | AN5: ='Pencapaian Join Event Activity'!I5 -> 0 | AO5: =SUM(AN5,AL5,AJ5,AH5,AF5,AD5,AB5,Z5,X5,U5) -> 1125000 | AP5: 0.059220836 | AQ5: =IF(AP5>=0.5%,-(AO5*10%),0) -> -112500 | AR5: 0 | AS5: =IF(AR5>0,-(AO5+AQ5),0) -> 0 | AT5: =SUM(AS5,AQ5,AO5) -> 1012500 | AU5: =AT5*55% -> 556875 | AV5: =AT5*45% -> 455625
B6: CABANG SUBANG | C6: ='Pencapaian Sales Value'!G34 -> 1.0046479 | D6: ='Pencapaian Product Focus'!H34 -> 1.0950658 | E6: ='Pencapaian Product Focus'!L34 -> 0.96428571 | F6: ='Pencapaian Effective Call'!G34 -> 0.91255814 | G6: ='Pencapaian New Open Outlet'!G34 -> 1.35 | H6: ='Pencapaian Active Outlet'!G34 -> 1.0622318 | N6: =AO34 -> 3933750 | Q6: BDG-SLS-GT-002 | R6: Cucu Yudi | S6: 3 Orang | T6: ='Pencapaian Sales Value'!G6 -> 1.0152433 | U6: ='Pencapaian Sales Value'!I6 -> 600000 | V6: ='Pencapaian Product Focus'!H6 -> 0.94132549 | W6: ='Pencapaian Product Focus'!L6 -> 0.95774648 | X6: ='Pencapaian Product Focus'!N6 -> 180000 | Y6: ='Pencapaian Effective Call'!G6 -> 1.0247593 | Z6: ='Pencapaian Effective Call'!I6 -> 180000 | AA6: ='Pencapaian New Open Outlet'!G6 -> 0 | AB6: ='Pencapaian New Open Outlet'!I6 -> 0 | AC6: ='Pencapaian Active Outlet'!G6 -> 1.0249307 | AD6: ='Pencapaian Active Outlet'!I6 -> 0 | AE6: ='Pencapaian Item per Outlet'!G6 -> 0.95710534 | AF6: ='Pencapaian Item per Outlet'!I6 -> 135000 | AG6: ='Pencapaian Product Display'!G6 -> 0 | AH6: ='Pencapaian Product Display'!I6 -> 0 | AI6: ='Pencapaian Sales Contract'!G6 -> 0 | AJ6: ='Pencapaian Sales Contract'!I6 -> 0 | AK6: ='Pencapaian Co-Branding'!G6 -> 0 | AL6: ='Pencapaian Co-Branding'!I6 -> 0 | AM6: ='Pencapaian Join Event Activity'!G6 -> 0 | AN6: ='Pencapaian Join Event Activity'!I6 -> 0 | AO6: =SUM(AN6,AL6,AJ6,AH6,AF6,AD6,AB6,Z6,X6,U6) -> 1095000 | AP6: 0 | AQ6: =IF(AP6>=0.5%,-(AO6*10%),0) -> 0 | AR6: 0 | AS6: =IF(AR6>0,-(AO6+AQ6),0) -> 0 | AT6: =SUM(AS6,AQ6,AO6) -> 1095000 | AU6: =AT6*55% -> 602250 | AV6: =AT6*45% -> 492750
B7: CABANG PURWAKARTA | C7: ='Pencapaian Sales Value'!G39 -> 0.95821433 | F7: ='Pencapaian Effective Call'!G39 -> 0.91868132 | G7: ='Pencapaian New Open Outlet'!G39 -> 0.14285714 | H7: ='Pencapaian Active Outlet'!G39 -> 1.104918 | N7: =AO39 -> 2602500 | Q7: BDG-SLS-GT-003 | R7: Iwa Setiawan | S7: 3 Orang | T7: ='Pencapaian Sales Value'!G7 -> 0.87141568 | U7: ='Pencapaian Sales Value'!I7 -> 300000 | V7: ='Pencapaian Product Focus'!H7 -> 0.97992095 | W7: ='Pencapaian Product Focus'!L7 -> 1 | X7: ='Pencapaian Product Focus'!N7 -> 210000 | Y7: ='Pencapaian Effective Call'!G7 -> 0.99268293 | Z7: ='Pencapaian Effective Call'!I7 -> 135000 | AA7: ='Pencapaian New Open Outlet'!G7 -> 0.25 | AB7: ='Pencapaian New Open Outlet'!I7 -> 0 | AC7: ='Pencapaian Active Outlet'!G7 -> 1.0163339 | AD7: ='Pencapaian Active Outlet'!I7 -> 0 | AE7: ='Pencapaian Item per Outlet'!G7 -> 0.95521542 | AF7: ='Pencapaian Item per Outlet'!I7 -> 135000 | AG7: ='Pencapaian Product Display'!G7 -> 0 | AH7: ='Pencapaian Product Display'!I7 -> 0 | AI7: ='Pencapaian Sales Contract'!G7 -> 0 | AJ7: ='Pencapaian Sales Contract'!I7 -> 0 | AK7: ='Pencapaian Co-Branding'!G7 -> 0 | AL7: ='Pencapaian Co-Branding'!I7 -> 0 | AM7: ='Pencapaian Join Event Activity'!G7 -> 0 | AN7: ='Pencapaian Join Event Activity'!I7 -> 0 | AO7: =SUM(AN7,AL7,AJ7,AH7,AF7,AD7,AB7,Z7,X7,U7) -> 780000 | AP7: 0 | AQ7: =IF(AP7>=0.5%,-(AO7*10%),0) -> 0 | AR7: 0 | AS7: =IF(AR7>0,-(AO7+AQ7),0) -> 0 | AT7: =SUM(AS7,AQ7,AO7) -> 780000 | AU7: =AT7*55% -> 429000 | AV7: =AT7*45% -> 351000
B8: TOTAL PENCAPAIAN AREA JAWA BARAT-1 | C8: ='Pencapaian Sales Value'!G40 -> 0.89525819 | D8: ='Pencapaian Product Focus'!H40 -> 0.93931294 | E8: ='Pencapaian Product Focus'!L40 -> 0.98344574 | F8: ='Pencapaian Effective Call'!G40 -> 0.92789788 | G8: ='Pencapaian New Open Outlet'!G40 -> 0.37654321 | H8: ='Pencapaian Active Outlet'!G40 -> 0.98463256 | I8: ='Pencapaian Item per Outlet'!G40 -> 0.79537525 | J8: ='Pencapaian Product Display'!G40 -> 0.89090909 | K8: ='Pencapaian Sales Contract'!G40 -> 0 | L8: ='Pencapaian Co-Branding'!G40 -> 0 | M8: ='Pencapaian Join Event Activity'!G40 -> 1 | N8: =SUM(N5:N7) -> 19484750 | Q8: BDG-SLS-GT-004 | R8: Dodhie Setiawan | S8: 3 Orang | T8: ='Pencapaian Sales Value'!G8 -> 0.84705993 | U8: ='Pencapaian Sales Value'!I8 -> 300000 | V8: ='Pencapaian Product Focus'!H8 -> 0.97616312 | W8: ='Pencapaian Product Focus'!L8 -> 0.96491228 | X8: ='Pencapaian Product Focus'!N8 -> 180000 | Y8: ='Pencapaian Effective Call'!G8 -> 1.0870445 | Z8: ='Pencapaian Effective Call'!I8 -> 180000 | AA8: ='Pencapaian New Open Outlet'!G8 -> 0 | AB8: ='Pencapaian New Open Outlet'!I8 -> 0 | AC8: ='Pencapaian Active Outlet'!G8 -> 1.0263158 | AD8: ='Pencapaian Active Outlet'!I8 -> 0 | AE8: ='Pencapaian Item per Outlet'!G8 -> 0.95682096 | AF8: ='Pencapaian Item per Outlet'!I8 -> 135000 | AG8: ='Pencapaian Product Display'!G8 -> 0 | AH8: ='Pencapaian Product Display'!I8 -> 0 | AI8: ='Pencapaian Sales Contract'!G8 -> 0 | AJ8: ='Pencapaian Sales Contract'!I8 -> 0 | AK8: ='Pencapaian Co-Branding'!G8 -> 0 | AL8: ='Pencapaian Co-Branding'!I8 -> 0 | AM8: ='Pencapaian Join Event Activity'!G8 -> 0 | AN8: ='Pencapaian Join Event Activity'!I8 -> 0 | AO8: =SUM(AN8,AL8,AJ8,AH8,AF8,AD8,AB8,Z8,X8,U8) -> 795000 | AP8: 0 | AQ8: =IF(AP8>=0.5%,-(AO8*10%),0) -> 0 | AR8: 0 | AS8: =IF(AR8>0,-(AO8+AQ8),0) -> 0 | AT8: =SUM(AS8,AQ8,AO8) -> 795000 | AU8: =AT8*55% -> 437250 | AV8: =AT8*45% -> 357750
Q9: BDG-SLS-GT-005 | R9: Sopian Kusmayana | S9: 2 Orang | T9: ='Pencapaian Sales Value'!G9 -> 0.81305826 | U9: ='Pencapaian Sales Value'!I9 -> 225000 | V9: ='Pencapaian Product Focus'!H9 -> 0.91225396 | W9: ='Pencapaian Product Focus'!L9 -> 0.90816327 | X9: ='Pencapaian Product Focus'!N9 -> 135000 | Y9: ='Pencapaian Effective Call'!G9 -> 0.94871795 | Z9: ='Pencapaian Effective Call'!I9 -> 101250 | AA9: ='Pencapaian New Open Outlet'!G9 -> 0.2 | AB9: ='Pencapaian New Open Outlet'!I9 -> 0 | AC9: ='Pencapaian Active Outlet'!G9 -> 1.0285255 | AD9: ='Pencapaian Active Outlet'!I9 -> 0 | AE9: ='Pencapaian Item per Outlet'!G9 -> 0.84796709 | AF9: ='Pencapaian Item per Outlet'!I9 -> 67500 | AG9: ='Pencapaian Product Display'!G9 -> 0 | AH9: ='Pencapaian Product Display'!I9 -> 0 | AI9: ='Pencapaian Sales Contract'!G9 -> 0 | AJ9: ='Pencapaian Sales Contract'!I9 -> 0 | AK9: ='Pencapaian Co-Branding'!G9 -> 0 | AL9: ='Pencapaian Co-Branding'!I9 -> 0 | AM9: ='Pencapaian Join Event Activity'!G9 -> 0 | AN9: ='Pencapaian Join Event Activity'!I9 -> 0 | AO9: =SUM(AN9,AL9,AJ9,AH9,AF9,AD9,AB9,Z9,X9,U9) -> 528750 | AP9: 0 | AQ9: =IF(AP9>=0.5%,-(AO9*10%),0) -> 0 | AR9: 0 | AS9: =IF(AR9>0,-(AO9+AQ9),0) -> 0 | AT9: =SUM(AS9,AQ9,AO9) -> 528750 | AU9: =AT9*70% -> 370125 | AV9: =AT9*30% -> 158625
B10: PENCAPAIAN AREA JAWA BARAT-2 | Q10: BDG-SLS-GT-006 | R10: Tri Aris Rusdiaman | S10: 2 Orang | T10: ='Pencapaian Sales Value'!G10 -> 0.82316348 | U10: ='Pencapaian Sales Value'!I10 -> 225000 | V10: ='Pencapaian Product Focus'!H10 -> 0.9632391 | W10: ='Pencapaian Product Focus'!L10 -> 0.95 | X10: ='Pencapaian Product Focus'!N10 -> 135000 | Y10: ='Pencapaian Effective Call'!G10 -> 0.87948718 | Z10: ='Pencapaian Effective Call'!I10 -> 67500 | AA10: ='Pencapaian New Open Outlet'!G10 -> 0 | AB10: ='Pencapaian New Open Outlet'!I10 -> 0 | AC10: ='Pencapaian Active Outlet'!G10 -> 1.0688259 | AD10: ='Pencapaian Active Outlet'!I10 -> 0 | AE10: ='Pencapaian Item per Outlet'!G10 -> 0.77174067 | AF10: ='Pencapaian Item per Outlet'!I10 -> 33750 | AG10: ='Pencapaian Product Display'!G10 -> 0 | AH10: ='Pencapaian Product Display'!I10 -> 0 | AI10: ='Pencapaian Sales Contract'!G10 -> 0 | AJ10: ='Pencapaian Sales Contract'!I10 -> 0 | AK10: ='Pencapaian Co-Branding'!G10 -> 0 | AL10: ='Pencapaian Co-Branding'!I10 -> 0 | AM10: ='Pencapaian Join Event Activity'!G10 -> 0 | AN10: ='Pencapaian Join Event Activity'!I10 -> 0 | AO10: =SUM(AN10,AL10,AJ10,AH10,AF10,AD10,AB10,Z10,X10,U10) -> 461250 | AP10: 0 | AQ10: =IF(AP10>=0.5%,-(AO10*10%),0) -> 0 | AR10: 0 | AS10: =IF(AR10>0,-(AO10+AQ10),0) -> 0 | AT10: =SUM(AS10,AQ10,AO10) -> 461250 | AU10: =AT10*70% -> 322875 | AV10: =AT10*30% -> 138375
B11: NAMA CABANG | C11: SALES VALUE | D11: PRODUCT FOCUS | F11: EFFECTIVE CALL | G11: NEW OPEN OUTLET | H11: ACTIVE OUTLET | I11: ITEM PER OUTLET | J11: PRODUCT DISPLAY | K11: SALES CONTRACT | L11: CO-BRANDING | M11: JOIN EVENT ACTIVITY | N11: TOTAL INSENTIF | Q11: BDG-SLS-GT-014 | R11: Agus Saeful | S11: MTC | T11: ='Pencapaian Sales Value'!G11 -> 1.0045631 | U11: ='Pencapaian Sales Value'!I11 -> 525000 | V11: ='Pencapaian Product Focus'!H11 -> 0 | W11: ='Pencapaian Product Focus'!L11 -> 0 | X11: ='Pencapaian Product Focus'!N11 -> 0 | Y11: ='Pencapaian Effective Call'!G11 -> 0 | Z11: ='Pencapaian Effective Call'!I11 -> 0 | AA11: ='Pencapaian New Open Outlet'!G11 -> 1.1 | AB11: ='Pencapaian New Open Outlet'!I11 -> 150000 | AC11: ='Pencapaian Active Outlet'!G11 -> 0.93333333 | AD11: ='Pencapaian Active Outlet'!I11 -> 75000 | AE11: ='Pencapaian Item per Outlet'!G11 -> 0 | AF11: ='Pencapaian Item per Outlet'!I11 -> 0 | AG11: ='Pencapaian Product Display'!G11 -> 0 | AH11: ='Pencapaian Product Display'!I11 -> 0 | AI11: ='Pencapaian Sales Contract'!G11 -> 0 | AJ11: ='Pencapaian Sales Contract'!I11 -> 0 | AK11: ='Pencapaian Co-Branding'!G11 -> 0 | AL11: ='Pencapaian Co-Branding'!I11 -> 0 | AM11: ='Pencapaian Join Event Activity'!G11 -> 0 | AN11: ='Pencapaian Join Event Activity'!I11 -> 0 | AO11: =SUM(AN11,AL11,AJ11,AH11,AF11,AD11,AB11,Z11,X11,U11) -> 750000 | AP11: 0 | AQ11: =IF(AP11>=0.5%,-(AO11*10%),0) -> 0 | AR11: 0 | AS11: =IF(AR11>0,-(AO11+AQ11),0) -> 0 | AT11: =SUM(AS11,AQ11,AO11) -> 750000 | AU11: =AT11*70% -> 525000 | AV11: =AT11*30% -> 225000
D12: VOLUME | E12: RO | Q12: BDG-SLS-GT-017 | R12: Deni Romansyah | S12: MTC | T12: ='Pencapaian Sales Value'!G12 -> 0 | U12: ='Pencapaian Sales Value'!I12 -> 0 | V12: ='Pencapaian Product Focus'!H12 -> 0 | W12: ='Pencapaian Product Focus'!L12 -> 0 | X12: ='Pencapaian Product Focus'!N12 -> 0 | Y12: ='Pencapaian Effective Call'!G12 -> 0 | Z12: ='Pencapaian Effective Call'!I12 -> 0 | AA12: ='Pencapaian New Open Outlet'!G12 -> 0 | AB12: ='Pencapaian New Open Outlet'!I12 -> 0 | AC12: ='Pencapaian Active Outlet'!G12 -> 0 | AD12: ='Pencapaian Active Outlet'!I12 -> 0 | AE12: ='Pencapaian Item per Outlet'!G12 -> 0 | AF12: ='Pencapaian Item per Outlet'!I12 -> 0 | AG12: ='Pencapaian Product Display'!G12 -> 0 | AH12: ='Pencapaian Product Display'!I12 -> 0 | AI12: ='Pencapaian Sales Contract'!G12 -> 0 | AJ12: ='Pencapaian Sales Contract'!I12 -> 0 | AK12: ='Pencapaian Co-Branding'!G12 -> 0 | AL12: ='Pencapaian Co-Branding'!I12 -> 0 | AM12: ='Pencapaian Join Event Activity'!G12 -> 0 | AN12: ='Pencapaian Join Event Activity'!I12 -> 0 | AO12: =SUM(AN12,AL12,AJ12,AH12,AF12,AD12,AB12,Z12,X12,U12) -> 0 | AP12: 0 | AQ12: =IF(AP12>=0.5%,-(AO12*10%),0) -> 0 | AR12: 0 | AS12: =IF(AR12>0,-(AO12+AQ12),0) -> 0 | AT12: =SUM(AS12,AQ12,AO12) -> 0 | AU12: =AT12*70% -> 0 | AV12: =AT12*30% -> 0
B13: CABANG GARUT | C13: ='Pencapaian Sales Value'!G64 -> 0.8607358 | D13: ='Pencapaian Product Focus'!H64 -> 0.75020833 | E13: ='Pencapaian Product Focus'!L64 -> 0.63037975 | F13: ='Pencapaian Effective Call'!G64 -> 0.99223529 | G13: ='Pencapaian New Open Outlet'!G64 -> 0.1941568 | H13: ='Pencapaian Active Outlet'!G64 -> 1.0290044 | I13: ='Pencapaian Item per Outlet'!G64 -> 0.54872827 | K13: ='Pencapaian Sales Contract'!G64 -> 0 | L13: ='Pencapaian Co-Branding'!G64 -> 0 | N13: =AO64 -> 4901500 | R13: ARIFIN SUFJAN | S13: SPV | T13: ='Pencapaian Sales Value'!G13 -> 0.91075133 | U13: ='Pencapaian Sales Value'!I13 -> 336000 | V13: ='Pencapaian Product Focus'!H13 -> 0.94234394 | W13: ='Pencapaian Product Focus'!L13 -> 0.96509863 | X13: ='Pencapaian Product Focus'!N13 -> 168000 | Y13: ='Pencapaian Effective Call'!G13 -> 1.0118604 | Z13: ='Pencapaian Effective Call'!I13 -> 0 | AA13: ='Pencapaian New Open Outlet'!G13 -> 0.33333333 | AB13: ='Pencapaian New Open Outlet'!I13 -> 0 | AC13: ='Pencapaian Active Outlet'!G13 -> 0.95386273 | AD13: ='Pencapaian Active Outlet'!I13 -> 168000 | AE13: ='Pencapaian Item per Outlet'!G13 -> 0.90679954 | AF13: ='Pencapaian Item per Outlet'!I13 -> 168000 | AG13: ='Pencapaian Product Display'!G13 -> 0 | AH13: ='Pencapaian Product Display'!I13 -> 0 | AI13: ='Pencapaian Sales Contract'!G13 -> 0 | AJ13: ='Pencapaian Sales Contract'!I13 -> 0 | AK13: ='Pencapaian Co-Branding'!G13 -> 0 | AL13: ='Pencapaian Co-Branding'!I13 -> 0 | AM13: ='Pencapaian Join Event Activity'!G13 -> 0 | AN13: ='Pencapaian Join Event Activity'!I13 -> 0 | AO13: =SUM(AN13,AL13,AJ13,AH13,AF13,AD13,AB13,Z13,X13,U13) -> 840000 | AP13: 0.015494819 | AQ13: =IF(AP13>=0.5%,-(AO13*10%),0) -> -84000 | AR13: 0 | AS13: =IF(AR13>0,-(AO13+AQ13),0) -> 0 | AT13: =SUM(AS13,AQ13,AO13) -> 756000 | AU13: =AT13 -> 756000 | AV13: 0
B14: CABANG TASIK | C14: ='Pencapaian Sales Value'!G71 -> 0.73837176 | D14: ='Pencapaian Product Focus'!H71 -> 0.70340278 | E14: ='Pencapaian Product Focus'!L71 -> 0.868 | F14: ='Pencapaian Effective Call'!G71 -> 0.65741935 | G14: ='Pencapaian New Open Outlet'!G71 -> 0.088407758 | H14: ='Pencapaian Active Outlet'!G71 -> 0.85245902 | I14: ='Pencapaian Item per Outlet'!G71 -> 0.50909091 | N14: =AO71 -> 1137750 | Q14: BDG-SLS-GT-007 | R14: Candra Irawan | S14: 3 Orang | T14: ='Pencapaian Sales Value'!G14 -> 0.91236266 | U14: ='Pencapaian Sales Value'!I14 -> 450000 | V14: ='Pencapaian Product Focus'!H14 -> 0.92679012 | W14: ='Pencapaian Product Focus'!L14 -> 0.98979592 | X14: ='Pencapaian Product Focus'!N14 -> 180000 | Y14: ='Pencapaian Effective Call'!G14 -> 0.99038462 | Z14: ='Pencapaian Effective Call'!I14 -> 135000 | AA14: ='Pencapaian New Open Outlet'!G14 -> 1.2 | AB14: ='Pencapaian New Open Outlet'!I14 -> 0 | AC14: ='Pencapaian Active Outlet'!G14 -> 0.98873239 | AD14: ='Pencapaian Active Outlet'!I14 -> 0 | AE14: ='Pencapaian Item per Outlet'!G14 -> 0.82783883 | AF14: ='Pencapaian Item per Outlet'!I14 -> 90000 | AG14: ='Pencapaian Product Display'!G14 -> 0 | AH14: ='Pencapaian Product Display'!I14 -> 0 | AI14: ='Pencapaian Sales Contract'!G14 -> 0 | AJ14: ='Pencapaian Sales Contract'!I14 -> 0 | AK14: ='Pencapaian Co-Branding'!G14 -> 0 | AL14: ='Pencapaian Co-Branding'!I14 -> 0 | AM14: ='Pencapaian Join Event Activity'!G14 -> 0 | AN14: ='Pencapaian Join Event Activity'!I14 -> 0 | AO14: =SUM(AN14,AL14,AJ14,AH14,AF14,AD14,AB14,Z14,X14,U14) -> 855000 | AP14: 0 | AQ14: =IF(AP14>=0.5%,-(AO14*10%),0) -> 0 | AR14: 0 | AS14: =IF(AR14>0,-(AO14+AQ14),0) -> 0 | AT14: =SUM(AS14,AQ14,AO14) -> 855000 | AU14: =AT14*55% -> 470250 | AV14: =AT14*45% -> 384750
B15: CABANG CIREBON | C15: ='Pencapaian Sales Value'!G76 -> 0.55375184 | F15: ='Pencapaian Effective Call'!G76 -> 0.51111111 | G15: ='Pencapaian New Open Outlet'!G76 -> 0.54166667 | H15: ='Pencapaian Active Outlet'!G76 -> 0.52763488 | N15: =AO76 -> 90000 | Q15: BDG-SLS-GT-008 | R15: Diki Andriana | S15: 3 Orang | T15: ='Pencapaian Sales Value'!G15 -> 0.80077877 | U15: ='Pencapaian Sales Value'!I15 -> 300000 | V15: ='Pencapaian Product Focus'!H15 -> 0.87667287 | W15: ='Pencapaian Product Focus'!L15 -> 1.0082645 | X15: ='Pencapaian Product Focus'!N15 -> 180000 | Y15: ='Pencapaian Effective Call'!G15 -> 0.83846154 | Z15: ='Pencapaian Effective Call'!I15 -> 90000 | AA15: ='Pencapaian New Open Outlet'!G15 -> 0 | AB15: ='Pencapaian New Open Outlet'!I15 -> 0 | AC15: ='Pencapaian Active Outlet'!G15 -> 1.0108696 | AD15: ='Pencapaian Active Outlet'!I15 -> 0 | AE15: ='Pencapaian Item per Outlet'!G15 -> 0.84946237 | AF15: ='Pencapaian Item per Outlet'!I15 -> 90000 | AG15: ='Pencapaian Product Display'!G15 -> 0 | AH15: ='Pencapaian Product Display'!I15 -> 0 | AI15: ='Pencapaian Sales Contract'!G15 -> 0 | AJ15: ='Pencapaian Sales Contract'!I15 -> 0 | AK15: ='Pencapaian Co-Branding'!G15 -> 0 | AL15: ='Pencapaian Co-Branding'!I15 -> 0 | AM15: ='Pencapaian Join Event Activity'!G15 -> 0 | AN15: ='Pencapaian Join Event Activity'!I15 -> 0 | AO15: =SUM(AN15,AL15,AJ15,AH15,AF15,AD15,AB15,Z15,X15,U15) -> 660000 | AP15: 0 | AQ15: =IF(AP15>=0.5%,-(AO15*10%),0) -> 0 | AR15: 0 | AS15: =IF(AR15>0,-(AO15+AQ15),0) -> 0 | AT15: =SUM(AS15,AQ15,AO15) -> 660000 | AU15: =AT15*55% -> 363000 | AV15: =AT15*45% -> 297000
B16: TOTAL PENCAPAIAN AREA JAWA BARAT-2 | C16: ='Pencapaian Sales Value'!G77 -> 0.82895215 | D16: ='Pencapaian Product Focus'!H77 -> 0.72680556 | E16: ='Pencapaian Product Focus'!L77 -> 0.72248062 | F16: ='Pencapaian Effective Call'!G77 -> 0.85014925 | G16: ='Pencapaian New Open Outlet'!G77 -> 0.2211776 | H16: ='Pencapaian Active Outlet'!G77 -> 0.89526293 | I16: ='Pencapaian Item per Outlet'!G77 -> 0.53551582 | K16: ='Pencapaian Sales Contract'!G77 -> 0 | L16: ='Pencapaian Co-Branding'!G77 -> 0 | N16: =SUM(N13:N15) -> 6129250 | Q16: BDG-SLS-GT-009 | R16: Kusada | S16: 3 Orang | T16: ='Pencapaian Sales Value'!G16 -> 0.89594636 | U16: ='Pencapaian Sales Value'!I16 -> 300000 | V16: ='Pencapaian Product Focus'!H16 -> 0.9138724 | W16: ='Pencapaian Product Focus'!L16 -> 0.936 | X16: ='Pencapaian Product Focus'!N16 -> 180000 | Y16: ='Pencapaian Effective Call'!G16 -> 0.86769231 | Z16: ='Pencapaian Effective Call'!I16 -> 90000 | AA16: ='Pencapaian New Open Outlet'!G16 -> 0.4 | AB16: ='Pencapaian New Open Outlet'!I16 -> 0 | AC16: ='Pencapaian Active Outlet'!G16 -> 0.87917738 | AD16: ='Pencapaian Active Outlet'!I16 -> 0 | AE16: ='Pencapaian Item per Outlet'!G16 -> 0.85982906 | AF16: ='Pencapaian Item per Outlet'!I16 -> 90000 | AG16: ='Pencapaian Product Display'!G16 -> 0 | AH16: ='Pencapaian Product Display'!I16 -> 0 | AI16: ='Pencapaian Sales Contract'!G16 -> 0 | AJ16: ='Pencapaian Sales Contract'!I16 -> 0 | AK16: ='Pencapaian Co-Branding'!G16 -> 0 | AL16: ='Pencapaian Co-Branding'!I16 -> 0 | AM16: ='Pencapaian Join Event Activity'!G16 -> 0 | AN16: ='Pencapaian Join Event Activity'!I16 -> 0 | AO16: =SUM(AN16,AL16,AJ16,AH16,AF16,AD16,AB16,Z16,X16,U16) -> 660000 | AP16: 0 | AQ16: =IF(AP16>=0.5%,-(AO16*10%),0) -> 0 | AR16: 0 | AS16: =IF(AR16>0,-(AO16+AQ16),0) -> 0 | AT16: =SUM(AS16,AQ16,AO16) -> 660000 | AU16: =AT16*55% -> 363000 | AV16: =AT16*45% -> 297000
Q17: BDG-SLS-GT-010 | R17: Peri Perdiansyah | S17: 3 Orang | T17: ='Pencapaian Sales Value'!G17 -> 0.91370605 | U17: ='Pencapaian Sales Value'!I17 -> 450000 | V17: ='Pencapaian Product Focus'!H17 -> 0.8351845 | W17: ='Pencapaian Product Focus'!L17 -> 1.029703 | X17: ='Pencapaian Product Focus'!N17 -> 180000 | Y17: ='Pencapaian Effective Call'!G17 -> 0.80769231 | Z17: ='Pencapaian Effective Call'!I17 -> 90000 | AA17: ='Pencapaian New Open Outlet'!G17 -> 0.2 | AB17: ='Pencapaian New Open Outlet'!I17 -> 0 | AC17: ='Pencapaian Active Outlet'!G17 -> 0.96 | AD17: ='Pencapaian Active Outlet'!I17 -> 0 | AE17: ='Pencapaian Item per Outlet'!G17 -> 1.0134771 | AF17: ='Pencapaian Item per Outlet'!I17 -> 180000 | AG17: ='Pencapaian Product Display'!G17 -> 0 | AH17: ='Pencapaian Product Display'!I17 -> 0 | AI17: ='Pencapaian Sales Contract'!G17 -> 0 | AJ17: ='Pencapaian Sales Contract'!I17 -> 0 | AK17: ='Pencapaian Co-Branding'!G17 -> 0 | AL17: ='Pencapaian Co-Branding'!I17 -> 0 | AM17: ='Pencapaian Join Event Activity'!G17 -> 0 | AN17: ='Pencapaian Join Event Activity'!I17 -> 0 | AO17: =SUM(AN17,AL17,AJ17,AH17,AF17,AD17,AB17,Z17,X17,U17) -> 900000 | AP17: 0 | AQ17: =IF(AP17>=0.5%,-(AO17*10%),0) -> 0 | AR17: 0 | AS17: =IF(AR17>0,-(AO17+AQ17),0) -> 0 | AT17: =SUM(AS17,AQ17,AO17) -> 900000 | AU17: =AT17*55% -> 495000 | AV17: =AT17*45% -> 405000
B18: PENCAPAIAN AREA JAWA BARAT-3 | Q18: BDG-SLS-GT-011 | R18: Ricat Batubara | S18: 3 Orang | T18: ='Pencapaian Sales Value'!G18 -> 0.84735592 | U18: ='Pencapaian Sales Value'!I18 -> 300000 | V18: ='Pencapaian Product Focus'!H18 -> 0.88937203 | W18: ='Pencapaian Product Focus'!L18 -> 1.0428571 | X18: ='Pencapaian Product Focus'!N18 -> 180000 | Y18: ='Pencapaian Effective Call'!G18 -> 0.78461538 | Z18: ='Pencapaian Effective Call'!I18 -> 45000 | AA18: ='Pencapaian New Open Outlet'!G18 -> 0.2 | AB18: ='Pencapaian New Open Outlet'!I18 -> 0 | AC18: ='Pencapaian Active Outlet'!G18 -> 0.87460815 | AD18: ='Pencapaian Active Outlet'!I18 -> 0 | AE18: ='Pencapaian Item per Outlet'!G18 -> 0.84792627 | AF18: ='Pencapaian Item per Outlet'!I18 -> 90000 | AG18: ='Pencapaian Product Display'!G18 -> 0 | AH18: ='Pencapaian Product Display'!I18 -> 0 | AI18: ='Pencapaian Sales Contract'!G18 -> 0 | AJ18: ='Pencapaian Sales Contract'!I18 -> 0 | AK18: ='Pencapaian Co-Branding'!G18 -> 0 | AL18: ='Pencapaian Co-Branding'!I18 -> 0 | AM18: ='Pencapaian Join Event Activity'!G18 -> 0 | AN18: ='Pencapaian Join Event Activity'!I18 -> 0 | AO18: =SUM(AN18,AL18,AJ18,AH18,AF18,AD18,AB18,Z18,X18,U18) -> 615000 | AP18: 0 | AQ18: =IF(AP18>=0.5%,-(AO18*10%),0) -> 0 | AR18: 0 | AS18: =IF(AR18>0,-(AO18+AQ18),0) -> 0 | AT18: =SUM(AS18,AQ18,AO18) -> 615000 | AU18: =AT18*55% -> 338250 | AV18: =AT18*45% -> 276750
B19: NAMA CABANG | C19: SALES VALUE | D19: PRODUCT FOCUS | F19: EFFECTIVE CALL | G19: NEW OPEN OUTLET | H19: ACTIVE OUTLET | I19: ITEM PER OUTLET | J19: PRODUCT DISPLAY | K19: SALES CONTRACT | L19: CO-BRANDING | M19: JOIN EVENT ACTIVITY | N19: TOTAL INSENTIF | Q19: BDG-SLS-GT-012 | R19: Jajang Faryana | S19: 2 Orang | T19: ='Pencapaian Sales Value'!G19 -> 0.80125671 | U19: ='Pencapaian Sales Value'!I19 -> 225000 | V19: ='Pencapaian Product Focus'!H19 -> 1.1469697 | W19: ='Pencapaian Product Focus'!L19 -> 1.0384615 | X19: ='Pencapaian Product Focus'!N19 -> 202500 | Y19: ='Pencapaian Effective Call'!G19 -> 0.732 | Z19: ='Pencapaian Effective Call'!I19 -> 33750 | AA19: ='Pencapaian New Open Outlet'!G19 -> 0 | AB19: ='Pencapaian New Open Outlet'!I19 -> 0 | AC19: ='Pencapaian Active Outlet'!G19 -> 0.92222222 | AD19: ='Pencapaian Active Outlet'!I19 -> 0 | AE19: ='Pencapaian Item per Outlet'!G19 -> 0.72289157 | AF19: ='Pencapaian Item per Outlet'!I19 -> 33750 | AG19: ='Pencapaian Product Display'!G19 -> 0 | AH19: ='Pencapaian Product Display'!I19 -> 0 | AI19: ='Pencapaian Sales Contract'!G19 -> 0 | AJ19: ='Pencapaian Sales Contract'!I19 -> 0 | AK19: ='Pencapaian Co-Branding'!G19 -> 0 | AL19: ='Pencapaian Co-Branding'!I19 -> 0 | AM19: ='Pencapaian Join Event Activity'!G19 -> 0 | AN19: ='Pencapaian Join Event Activity'!I19 -> 0 | AO19: =SUM(AN19,AL19,AJ19,AH19,AF19,AD19,AB19,Z19,X19,U19) -> 495000 | AP19: 0.002133449 | AQ19: =IF(AP19>=0.5%,-(AO19*10%),0) -> 0 | AR19: 0.002133449 | AS19: =IF(AR19>0,-(AO19+AQ19),0) -> -495000 | AT19: =SUM(AS19,AQ19,AO19) -> 0 | AU19: =AT19*70% -> 0 | AV19: =AT19*30% -> 0
D20: VOLUME | E20: RO | R20: Ende Taryana | S20: 3 Orang | T20: ='Pencapaian Sales Value'!G20 -> 0.8877964 | U20: ='Pencapaian Sales Value'!I20 -> 300000 | V20: ='Pencapaian Product Focus'!H20 -> 0.99045507 | W20: ='Pencapaian Product Focus'!L20 -> 1.0873016 | X20: ='Pencapaian Product Focus'!N20 -> 210000 | Y20: ='Pencapaian Effective Call'!G20 -> 0.97538462 | Z20: ='Pencapaian Effective Call'!I20 -> 135000 | AA20: ='Pencapaian New Open Outlet'!G20 -> 0 | AB20: ='Pencapaian New Open Outlet'!I20 -> 0 | AC20: ='Pencapaian Active Outlet'!G20 -> 1.0632911 | AD20: ='Pencapaian Active Outlet'!I20 -> 0 | AE20: ='Pencapaian Item per Outlet'!G20 -> 0.95892857 | AF20: ='Pencapaian Item per Outlet'!I20 -> 135000 | AG20: ='Pencapaian Product Display'!G20 -> 0 | AH20: ='Pencapaian Product Display'!I20 -> 0 | AI20: ='Pencapaian Sales Contract'!G20 -> 0 | AJ20: ='Pencapaian Sales Contract'!I20 -> 0 | AK20: ='Pencapaian Co-Branding'!G20 -> 0 | AL20: ='Pencapaian Co-Branding'!I20 -> 0 | AM20: ='Pencapaian Join Event Activity'!G20 -> 0 | AN20: ='Pencapaian Join Event Activity'!I20 -> 0 | AO20: =SUM(AN20,AL20,AJ20,AH20,AF20,AD20,AB20,Z20,X20,U20) -> 780000 | AP20: 0 | AQ20: =IF(AP20>=0.5%,-(AO20*10%),0) -> 0 | AR20: 0 | AS20: =IF(AR20>0,-(AO20+AQ20),0) -> 0 | AT20: =SUM(AS20,AQ20,AO20) -> 780000 | AU20: =AT20*55% -> 429000 | AV20: =AT20*45% -> 351000
B21: CABANG SUKABUMI | C21: ='Pencapaian Sales Value'!G90 -> 0.65077411 | F21: ='Pencapaian Effective Call'!G90 -> 0.768 | G21: ='Pencapaian New Open Outlet'!G90 -> 2.25 | H21: ='Pencapaian Active Outlet'!G90 -> 1.0430769 | N21: =AO90 -> 1648500 | R21: ENDY AFRIANA NUGRAHA | S21: SPV | T21: ='Pencapaian Sales Value'!G21 -> 0.87325468 | U21: ='Pencapaian Sales Value'!I21 -> 216000 | V21: ='Pencapaian Product Focus'!H21 -> 0.9114619 | W21: ='Pencapaian Product Focus'!L21 -> 1.0149925 | X21: ='Pencapaian Product Focus'!N21 -> 204000 | Y21: ='Pencapaian Effective Call'!G21 -> 0.87052342 | Z21: ='Pencapaian Effective Call'!I21 -> 0 | AA21: ='Pencapaian New Open Outlet'!G21 -> 0.28571429 | AB21: ='Pencapaian New Open Outlet'!I21 -> 0 | AC21: ='Pencapaian Active Outlet'!G21 -> 0.96034696 | AD21: ='Pencapaian Active Outlet'!I21 -> 168000 | AE21: ='Pencapaian Item per Outlet'!G21 -> 0.8792399 | AF21: ='Pencapaian Item per Outlet'!I21 -> 108000 | AG21: ='Pencapaian Product Display'!G21 -> 0 | AH21: ='Pencapaian Product Display'!I21 -> 0 | AI21: ='Pencapaian Sales Contract'!G21 -> 0 | AJ21: ='Pencapaian Sales Contract'!I21 -> 0 | AK21: ='Pencapaian Co-Branding'!G21 -> 0 | AL21: ='Pencapaian Co-Branding'!I21 -> 0 | AM21: ='Pencapaian Join Event Activity'!G21 -> 0 | AN21: ='Pencapaian Join Event Activity'!I21 -> 0 | AO21: =SUM(AN21,AL21,AJ21,AH21,AF21,AD21,AB21,Z21,X21,U21) -> 696000 | AP21: 0.00011348463 | AQ21: =IF(AP21>=0.5%,-(AO21*10%),0) -> 0 | AR21: 0.00011348463 | AS21: =IF(AR21>0,-(AO21+AQ21),0) -> -696000 | AT21: =SUM(AS21,AQ21,AO21) -> 0 | AU21: =AT21 -> 0 | AV21: 0
B22: CABANG BOGOR | C22: ='Pencapaian Sales Value'!G94 -> 0.75324508 | F22: ='Pencapaian Effective Call'!G94 -> 0.61013986 | G22: ='Pencapaian New Open Outlet'!G94 -> 0.3 | H22: ='Pencapaian Active Outlet'!G94 -> 0.68924303 | N22: =AO94 -> 435000 | Q22: BDG-SLS-HRC-001 | R22: Gita Rosita | S22: AE | T22: ='Pencapaian Sales Value'!G22 -> 0.6407313 | U22: ='Pencapaian Sales Value'!I22 -> 0 | V22: ='Pencapaian Product Focus'!H22 -> 0 | W22: ='Pencapaian Product Focus'!L22 -> 0 | X22: ='Pencapaian Product Focus'!N22 -> 0 | Y22: ='Pencapaian Effective Call'!G22 -> 0 | Z22: ='Pencapaian Effective Call'!I22 -> 0 | AA22: ='Pencapaian New Open Outlet'!G22 -> 0.2 | AB22: ='Pencapaian New Open Outlet'!I22 -> 0 | AC22: ='Pencapaian Active Outlet'!G22 -> 0.4 | AD22: ='Pencapaian Active Outlet'!I22 -> 0 | AE22: ='Pencapaian Item per Outlet'!G22 -> 0 | AF22: ='Pencapaian Item per Outlet'!I22 -> 0 | AG22: ='Pencapaian Product Display'!G22 -> 0 | AH22: ='Pencapaian Product Display'!I22 -> 0 | AI22: ='Pencapaian Sales Contract'!G22 -> 0 | AJ22: ='Pencapaian Sales Contract'!I22 -> 0 | AK22: ='Pencapaian Co-Branding'!G22 -> 0 | AL22: ='Pencapaian Co-Branding'!I22 -> 0 | AM22: ='Pencapaian Join Event Activity'!G22 -> 0 | AN22: ='Pencapaian Join Event Activity'!I22 -> 0 | AO22: =SUM(AN22,AL22,AJ22,AH22,AF22,AD22,AB22,Z22,X22,U22) -> 0 | AP22: 0.0049192365 | AQ22: =IF(AP22>=0.5%,-(AO22*10%),0) -> 0 | AR22: 0 | AS22: =IF(AR22>0,-(AO22+AQ22),0) -> 0 | AT22: =SUM(AS22,AQ22,AO22) -> 0 | AU22: =AT22 -> 0 | AV22: 0
B23: TOTAL PENCAPAIAN AREA JAWA BARAT-3 | C23: ='Pencapaian Sales Value'!G95 -> 0.71673365 | F23: ='Pencapaian Effective Call'!G95 -> 0.69969743 | G23: ='Pencapaian New Open Outlet'!G95 -> 1.275 | H23: ='Pencapaian Active Outlet'!G95 -> 0.88888889 | N23: =SUM(N21:N22) -> 2083500 | Q23: BDG-SLS-HRC-002 | R23: Dina Apriani | S23: AE | T23: ='Pencapaian Sales Value'!G23 -> 0.87744112 | U23: ='Pencapaian Sales Value'!I23 -> 130000 | V23: ='Pencapaian Product Focus'!H23 -> 0 | W23: ='Pencapaian Product Focus'!L23 -> 0 | X23: ='Pencapaian Product Focus'!N23 -> 0 | Y23: ='Pencapaian Effective Call'!G23 -> 0 | Z23: ='Pencapaian Effective Call'!I23 -> 0 | AA23: ='Pencapaian New Open Outlet'!G23 -> 0.2 | AB23: ='Pencapaian New Open Outlet'!I23 -> 0 | AC23: ='Pencapaian Active Outlet'!G23 -> 0.90909091 | AD23: ='Pencapaian Active Outlet'!I23 -> 98000 | AE23: ='Pencapaian Item per Outlet'!G23 -> 0 | AF23: ='Pencapaian Item per Outlet'!I23 -> 0 | AG23: ='Pencapaian Product Display'!G23 -> 0 | AH23: ='Pencapaian Product Display'!I23 -> 0 | AI23: ='Pencapaian Sales Contract'!G23 -> 0 | AJ23: ='Pencapaian Sales Contract'!I23 -> 0 | AK23: ='Pencapaian Co-Branding'!G23 -> 0 | AL23: ='Pencapaian Co-Branding'!I23 -> 0 | AM23: ='Pencapaian Join Event Activity'!G23 -> 0 | AN23: ='Pencapaian Join Event Activity'!I23 -> 0 | AO23: =SUM(AN23,AL23,AJ23,AH23,AF23,AD23,AB23,Z23,X23,U23) -> 228000 | AP23: 0.029823281 | AQ23: =IF(AP23>=0.5%,-(AO23*10%),0) -> -22800 | AR23: 0 | AS23: =IF(AR23>0,-(AO23+AQ23),0) -> 0 | AT23: =SUM(AS23,AQ23,AO23) -> 205200 | AU23: =AT23 -> 205200 | AV23: 0
R24: USDEK RIYANTO | S24: SPV | T24: ='Pencapaian Sales Value'!G24 -> 0.74853023 | U24: ='Pencapaian Sales Value'!I24 -> 110000 | V24: ='Pencapaian Product Focus'!H24 -> 0 | W24: ='Pencapaian Product Focus'!L24 -> 0 | X24: ='Pencapaian Product Focus'!N24 -> 0 | Y24: ='Pencapaian Effective Call'!G24 -> 0 | Z24: ='Pencapaian Effective Call'!I24 -> 0 | AA24: ='Pencapaian New Open Outlet'!G24 -> 0.2 | AB24: ='Pencapaian New Open Outlet'!I24 -> 0 | AC24: ='Pencapaian Active Outlet'!G24 -> 0.69473684 | AD24: ='Pencapaian Active Outlet'!I24 -> 0 | AE24: ='Pencapaian Item per Outlet'!G24 -> 0 | AF24: ='Pencapaian Item per Outlet'!I24 -> 0 | AG24: ='Pencapaian Product Display'!G24 -> 0 | AH24: ='Pencapaian Product Display'!I24 -> 0 | AI24: ='Pencapaian Sales Contract'!G24 -> 0 | AJ24: ='Pencapaian Sales Contract'!I24 -> 0 | AK24: ='Pencapaian Co-Branding'!G24 -> 0 | AL24: ='Pencapaian Co-Branding'!I24 -> 0 | AM24: ='Pencapaian Join Event Activity'!G24 -> 1 | AN24: ='Pencapaian Join Event Activity'!I24 -> 50000 | AO24: =SUM(AN24,AL24,AJ24,AH24,AF24,AD24,AB24,Z24,X24,U24) -> 160000 | AP24: 0.018218764 | AQ24: =IF(AP24>=0.5%,-(AO24*10%),0) -> -16000 | AR24: 0 | AS24: =IF(AR24>0,-(AO24+AQ24),0) -> 0 | AT24: =SUM(AS24,AQ24,AO24) -> 144000 | AU24: =AT24 -> 144000 | AV24: 0
B25: PENCAPAIAN AREA JAWA TENGAH | Q25: BDG-SLS-MT-001 | R25: Dian Fitriani | S25: KAE | T25: ='Pencapaian Sales Value'!G25 -> 0.61852159 | U25: ='Pencapaian Sales Value'!I25 -> 0 | V25: ='Pencapaian Product Focus'!H25 -> 0.87777778 | W25: ='Pencapaian Product Focus'!L25 -> 0.73333333 | X25: ='Pencapaian Product Focus'!N25 -> 48500 | Y25: ='Pencapaian Effective Call'!G25 -> 0.78666667 | Z25: ='Pencapaian Effective Call'!I25 -> 16000 | AA25: ='Pencapaian New Open Outlet'!G25 -> 0.2 | AB25: ='Pencapaian New Open Outlet'!I25 -> 0 | AC25: ='Pencapaian Active Outlet'!G25 -> #DIV/0! | AD25: ='Pencapaian Active Outlet'!I25 -> 0 | AE25: ='Pencapaian Item per Outlet'!G25 -> 0.59166667 | AF25: ='Pencapaian Item per Outlet'!I25 -> 0 | AG25: ='Pencapaian Product Display'!G25 -> 0.86666667 | AH25: ='Pencapaian Product Display'!I25 -> 0 | AI25: ='Pencapaian Sales Contract'!G25 -> 0 | AJ25: ='Pencapaian Sales Contract'!I25 -> 0 | AK25: ='Pencapaian Co-Branding'!G25 -> 0 | AL25: ='Pencapaian Co-Branding'!I25 -> 0 | AM25: ='Pencapaian Join Event Activity'!G25 -> 0 | AN25: ='Pencapaian Join Event Activity'!I25 -> 0 | AO25: =SUM(AN25,AL25,AJ25,AH25,AF25,AD25,AB25,Z25,X25,U25) -> 64500 | AP25: 0.41022691 | AQ25: =IF(AP25>=0.5%,-(AO25*10%),0) -> -6450 | AR25: 0 | AS25: =IF(AR25>0,-(AO25+AQ25),0) -> 0 | AT25: =SUM(AS25,AQ25,AO25) -> 58050 | AU25: =AT25 -> 58050 | AV25: 0
B26: NAMA CABANG | C26: SALES VALUE | D26: PRODUCT FOCUS | F26: EFFECTIVE CALL | G26: NEW OPEN OUTLET | H26: ACTIVE OUTLET | I26: ITEM PER OUTLET | J26: PRODUCT DISPLAY | K26: SALES CONTRACT | L26: CO-BRANDING | M26: JOIN EVENT ACTIVITY | N26: TOTAL INSENTIF | Q26: BDG-SLS-MT-002 | R26: Dinda Dewi Maharani | S26: KAE | T26: ='Pencapaian Sales Value'!G26 -> 0.80266516 | U26: ='Pencapaian Sales Value'!I26 -> 162500 | V26: ='Pencapaian Product Focus'!H26 -> 0.4 | W26: ='Pencapaian Product Focus'!L26 -> 1 | X26: ='Pencapaian Product Focus'!N26 -> 65000 | Y26: ='Pencapaian Effective Call'!G26 -> 0.85454545 | Z26: ='Pencapaian Effective Call'!I26 -> 32500 | AA26: ='Pencapaian New Open Outlet'!G26 -> 0 | AB26: ='Pencapaian New Open Outlet'!I26 -> 0 | AC26: ='Pencapaian Active Outlet'!G26 -> #DIV/0! | AD26: ='Pencapaian Active Outlet'!I26 -> 0 | AE26: ='Pencapaian Item per Outlet'!G26 -> 0.56321839 | AF26: ='Pencapaian Item per Outlet'!I26 -> 0 | AG26: ='Pencapaian Product Display'!G26 -> 0.92 | AH26: ='Pencapaian Product Display'!I26 -> 0 | AI26: ='Pencapaian Sales Contract'!G26 -> 0 | AJ26: ='Pencapaian Sales Contract'!I26 -> 0 | AK26: ='Pencapaian Co-Branding'!G26 -> 0 | AL26: ='Pencapaian Co-Branding'!I26 -> 0 | AM26: ='Pencapaian Join Event Activity'!G26 -> 0 | AN26: ='Pencapaian Join Event Activity'!I26 -> 0 | AO26: =SUM(AN26,AL26,AJ26,AH26,AF26,AD26,AB26,Z26,X26,U26) -> 260000 | AP26: 0.26249418 | AQ26: =IF(AP26>=0.5%,-(AO26*10%),0) -> -26000 | AR26: 0.009128434 | AS26: =IF(AR26>0,-(AO26+AQ26),0) -> -234000 | AT26: =SUM(AS26,AQ26,AO26) -> 0 | AU26: =AT26 -> 0 | AV26: 0
D27: VOLUME | E27: RO | R27: CATUR ATOT RISTADIN | S27: SPV | T27: ='Pencapaian Sales Value'!G27 -> 0.70172623 | U27: ='Pencapaian Sales Value'!I27 -> 120000 | V27: ='Pencapaian Product Focus'!H27 -> 0.68666667 | W27: ='Pencapaian Product Focus'!L27 -> 0.84 | X27: ='Pencapaian Product Focus'!N27 -> 0 | Y27: ='Pencapaian Effective Call'!G27 -> 0.81538462 | Z27: ='Pencapaian Effective Call'!I27 -> 40000 | AA27: ='Pencapaian New Open Outlet'!G27 -> 0.1 | AB27: ='Pencapaian New Open Outlet'!I27 -> 0 | AC27: ='Pencapaian Active Outlet'!G27 -> #DIV/0! | AD27: ='Pencapaian Active Outlet'!I27 -> 0 | AE27: ='Pencapaian Item per Outlet'!G27 -> 0.57744253 | AF27: ='Pencapaian Item per Outlet'!I27 -> 0 | AG27: ='Pencapaian Product Display'!G27 -> 0.89090909 | AH27: ='Pencapaian Product Display'!I27 -> 40000 | AI27: ='Pencapaian Sales Contract'!G27 -> 0 | AJ27: ='Pencapaian Sales Contract'!I27 -> 0 | AK27: ='Pencapaian Co-Branding'!G27 -> 0 | AL27: ='Pencapaian Co-Branding'!I27 -> 0 | AM27: ='Pencapaian Join Event Activity'!G27 -> 0 | AN27: ='Pencapaian Join Event Activity'!I27 -> 0 | AO27: =SUM(AN27,AL27,AJ27,AH27,AF27,AD27,AB27,Z27,X27,U27) -> 200000 | AP27: 0.32255815 | AQ27: =IF(AP27>=0.5%,-(AO27*10%),0) -> -20000 | AR27: 0.0045580746 | AS27: =IF(AR27>0,-(AO27+AQ27),0) -> -180000 | AT27: =SUM(AS27,AQ27,AO27) -> 0 | AU27: =AT27 -> 0 | AV27: 0
B28: CABANG TEGAL | C28: ='Pencapaian Sales Value'!G109 -> 0.74106037 | D28: ='Pencapaian Product Focus'!H109 -> 0.98861111 | E28: ='Pencapaian Product Focus'!L109 -> 0.564 | F28: ='Pencapaian Effective Call'!G109 -> 0.84285714 | G28: ='Pencapaian New Open Outlet'!G109 -> 0.46153846 | H28: ='Pencapaian Active Outlet'!G109 -> 0.825 | N28: =AO109 -> 829500 | R28: TOTAL CABANG BANDUNG | T28: ='Pencapaian Sales Value'!G28 -> 0.88311921 | U28: ='Pencapaian Sales Value'!I28 -> 6174500 | V28: ='Pencapaian Product Focus'!H28 -> 0.92620649 | W28: ='Pencapaian Product Focus'!L28 -> 0.98741673 | X28: ='Pencapaian Product Focus'!N28 -> 2848000 | Y28: ='Pencapaian Effective Call'!G28 -> 0.93160483 | Z28: ='Pencapaian Effective Call'!I28 -> 1551000 | AA28: ='Pencapaian New Open Outlet'!G28 -> 0.27102804 | AB28: ='Pencapaian New Open Outlet'!I28 -> 150000 | AC28: ='Pencapaian Active Outlet'!G28 -> 0.94270668 | AD28: ='Pencapaian Active Outlet'!I28 -> 509000 | AE28: ='Pencapaian Item per Outlet'!G28 -> 0.79537525 | AF28: ='Pencapaian Item per Outlet'!I28 -> 1626000 | AG28: ='Pencapaian Product Display'!G28 -> 0.89090909 | AH28: ='Pencapaian Product Display'!I28 -> 40000 | AI28: ='Pencapaian Sales Contract'!G28 -> 0 | AJ28: ='Pencapaian Sales Contract'!I28 -> 0 | AK28: ='Pencapaian Co-Branding'!G28 -> 0 | AL28: ='Pencapaian Co-Branding'!I28 -> 0 | AM28: ='Pencapaian Join Event Activity'!G28 -> 1 | AN28: ='Pencapaian Join Event Activity'!I28 -> 50000 | AO28: =SUM(AN28,AL28,AJ28,AH28,AF28,AD28,AB28,Z28,X28,U28) -> 12948500 | AP28: 0.010519746 | AQ28: =SUM(AQ5:AQ27) -> -287750 | AR28: 9.6859241e-05 | AS28: =SUM(AS5:AS27) -> -1605000 | AT28: =SUM(AS28,AQ28,AO28) -> 11055750 | AU28: =SUM(AU5:AU27) -> 6865125 | AV28: =SUM(AV5:AV27) -> 4190625
B29: CABANG WANGON | C29: ='Pencapaian Sales Value'!G115 -> 0.75907664 | D29: ='Pencapaian Product Focus'!H115 -> 0.74888889 | E29: ='Pencapaian Product Focus'!L115 -> 0.68421053 | F29: ='Pencapaian Effective Call'!G115 -> 0.88468468 | G29: ='Pencapaian New Open Outlet'!G115 -> 0.40625 | H29: ='Pencapaian Active Outlet'!G115 -> 0.80508475 | N29: =AO115 -> 1033500 | P29: SUBANG | Q29: SBG-SLS-GT-001 | R29: Mansyur | S29: 3 Orang | T29: ='Pencapaian Sales Value'!G29 -> 1.0094697 | U29: ='Pencapaian Sales Value'!I29 -> 600000 | V29: ='Pencapaian Product Focus'!H29 -> 1.1028 | W29: ='Pencapaian Product Focus'!L29 -> 0.96428571 | X29: ='Pencapaian Product Focus'!N29 -> 240000 | Y29: ='Pencapaian Effective Call'!G29 -> 1.0875 | Z29: ='Pencapaian Effective Call'!I29 -> 180000 | AA29: ='Pencapaian New Open Outlet'!G29 -> 1.3333333 | AB29: ='Pencapaian New Open Outlet'!I29 -> 225000 | AC29: ='Pencapaian Active Outlet'!G29 -> 1.0584416 | AD29: ='Pencapaian Active Outlet'!I29 -> 0 | AE29: ='Pencapaian Item per Outlet'!G29 -> 0 | AF29: ='Pencapaian Item per Outlet'!I29 -> 0 | AG29: ='Pencapaian Product Display'!G29 -> 0 | AH29: ='Pencapaian Product Display'!I29 -> 0 | AI29: ='Pencapaian Sales Contract'!G29 -> 0 | AJ29: ='Pencapaian Sales Contract'!I29 -> 0 | AK29: ='Pencapaian Co-Branding'!G29 -> 0 | AL29: ='Pencapaian Co-Branding'!I29 -> 0 | AM29: ='Pencapaian Join Event Activity'!G29 -> 0 | AN29: ='Pencapaian Join Event Activity'!I29 -> 0 | AO29: =SUM(AN29,AL29,AJ29,AH29,AF29,AD29,AB29,Z29,X29,U29) -> 1245000 | AP29: 0 | AQ29: =IF(AP29>=0.5%,-(AO29*10%),0) -> 0 | AR29: 0 | AS29: =IF(AR29>0,-(AO29+AQ29),0) -> 0 | AT29: =SUM(AS29,AQ29,AO29) -> 1245000 | AU29: =AT29*55% -> 684750 | AV29: =AT29*45% -> 560250
B30: CABANG WONOSOBO - KEBUMEN | C30: ='Pencapaian Sales Value'!G128 -> 0.78995614 | D30: ='Pencapaian Product Focus'!H128 -> 1.091954 | E30: ='Pencapaian Product Focus'!L128 -> 0.54333333 | F30: ='Pencapaian Effective Call'!G133 -> 0.69444444 | G30: ='Pencapaian New Open Outlet'!G128 -> 0.275 | H30: ='Pencapaian Active Outlet'!G133 -> 0.80454545 | N30: =AO128 -> 1043250 | Q30: SBG-SLS-GT-002 | R30: Sujiarto | S30: 2 Orang | T30: ='Pencapaian Sales Value'!G30 -> 1.0317739 | U30: ='Pencapaian Sales Value'!I30 -> 450000 | V30: ='Pencapaian Product Focus'!H30 -> 1.0909091 | W30: ='Pencapaian Product Focus'!L30 -> 0.93333333 | X30: ='Pencapaian Product Focus'!N30 -> 157500 | Y30: ='Pencapaian Effective Call'!G30 -> 0.91466667 | Z30: ='Pencapaian Effective Call'!I30 -> 101250 | AA30: ='Pencapaian New Open Outlet'!G30 -> 2 | AB30: ='Pencapaian New Open Outlet'!I30 -> 168750 | AC30: ='Pencapaian Active Outlet'!G30 -> 1.009434 | AD30: ='Pencapaian Active Outlet'!I30 -> 0 | AE30: ='Pencapaian Item per Outlet'!G30 -> 0 | AF30: ='Pencapaian Item per Outlet'!I30 -> 0 | AG30: ='Pencapaian Product Display'!G30 -> 0 | AH30: ='Pencapaian Product Display'!I30 -> 0 | AI30: ='Pencapaian Sales Contract'!G30 -> 0 | AJ30: ='Pencapaian Sales Contract'!I30 -> 0 | AK30: ='Pencapaian Co-Branding'!G30 -> 0 | AL30: ='Pencapaian Co-Branding'!I30 -> 0 | AM30: ='Pencapaian Join Event Activity'!G30 -> 0 | AN30: ='Pencapaian Join Event Activity'!I30 -> 0 | AO30: =SUM(AN30,AL30,AJ30,AH30,AF30,AD30,AB30,Z30,X30,U30) -> 877500 | AP30: 0 | AQ30: =IF(AP30>=0.5%,-(AO30*10%),0) -> 0 | AR30: 0 | AS30: =IF(AR30>0,-(AO30+AQ30),0) -> 0 | AT30: =SUM(AS30,AQ30,AO30) -> 877500 | AU30: =AT30*70% -> 614250 | AV30: =AT30*30% -> 263250
B31: CABANG SEMARANG | C31: ='Pencapaian Sales Value'!G133 -> 0.32588611 | F31: ='Pencapaian Effective Call'!G133 -> 0.69444444 | G31: ='Pencapaian New Open Outlet'!G133 -> 0.69230769 | H31: ='Pencapaian Active Outlet'!G133 -> 0.80454545 | N31: =AO133 -> 468000 | R31: (Vacant) | T31: ='Pencapaian Sales Value'!G31 -> 0 | U31: ='Pencapaian Sales Value'!I31 -> 0 | V31: ='Pencapaian Product Focus'!H31 -> 0 | W31: ='Pencapaian Product Focus'!L31 -> 0 | X31: ='Pencapaian Product Focus'!N31 -> 0 | Y31: ='Pencapaian Effective Call'!G31 -> 0 | Z31: ='Pencapaian Effective Call'!I31 -> 0 | AA31: ='Pencapaian New Open Outlet'!G31 -> 0 | AB31: ='Pencapaian New Open Outlet'!I31 -> 0 | AC31: ='Pencapaian Active Outlet'!G31 -> #DIV/0! | AD31: ='Pencapaian Active Outlet'!I31 -> 0 | AE31: ='Pencapaian Item per Outlet'!G31 -> 0 | AF31: ='Pencapaian Item per Outlet'!I31 -> 0 | AG31: ='Pencapaian Product Display'!G31 -> 0 | AH31: ='Pencapaian Product Display'!I31 -> 0 | AI31: ='Pencapaian Sales Contract'!G31 -> 0 | AJ31: ='Pencapaian Sales Contract'!I31 -> 0 | AK31: ='Pencapaian Co-Branding'!G31 -> 0 | AL31: ='Pencapaian Co-Branding'!I31 -> 0 | AM31: ='Pencapaian Join Event Activity'!G31 -> 0 | AN31: ='Pencapaian Join Event Activity'!I31 -> 0 | AO31: =SUM(AN31,AL31,AJ31,AH31,AF31,AD31,AB31,Z31,X31,U31) -> 0 | AP31: 0 | AQ31: =IF(AP31>=0.5%,-(AO31*10%),0) -> 0 | AR31: 0 | AS31: =IF(AR31>0,-(AO31+AQ31),0) -> 0 | AT31: =SUM(AS31,AQ31,AO31) -> 0
B32: CABANG SOLO | C32: ='Pencapaian Sales Value'!G146 -> 0.25089459 | H32: ='Pencapaian Active Outlet'!G146 -> 0.421875 | N32: =AO146 -> 198000 | Q32: SBG-SLS-GT-003 | R32: Agus Geri Gustiana | S32: 2 Orang | T32: ='Pencapaian Sales Value'!G32 -> 0.85903128 | U32: ='Pencapaian Sales Value'!I32 -> 225000 | V32: ='Pencapaian Product Focus'!H32 -> 0.92 | W32: ='Pencapaian Product Focus'!L32 -> 1.02 | X32: ='Pencapaian Product Focus'!N32 -> 157500 | Y32: ='Pencapaian Effective Call'!G32 -> 0.67666667 | Z32: ='Pencapaian Effective Call'!I32 -> 0 | AA32: ='Pencapaian New Open Outlet'!G32 -> 1.2666667 | AB32: ='Pencapaian New Open Outlet'!I32 -> 168750 | AC32: ='Pencapaian Active Outlet'!G32 -> 1.18 | AD32: ='Pencapaian Active Outlet'!I32 -> 0 | AE32: ='Pencapaian Item per Outlet'!G32 -> 0 | AF32: ='Pencapaian Item per Outlet'!I32 -> 0 | AG32: ='Pencapaian Product Display'!G32 -> 0 | AH32: ='Pencapaian Product Display'!I32 -> 0 | AI32: ='Pencapaian Sales Contract'!G32 -> 0 | AJ32: ='Pencapaian Sales Contract'!I32 -> 0 | AK32: ='Pencapaian Co-Branding'!G32 -> 0 | AL32: ='Pencapaian Co-Branding'!I32 -> 0 | AM32: ='Pencapaian Join Event Activity'!G32 -> 0 | AN32: ='Pencapaian Join Event Activity'!I32 -> 0 | AO32: =SUM(AN32,AL32,AJ32,AH32,AF32,AD32,AB32,Z32,X32,U32) -> 551250 | AP32: 0 | AQ32: =IF(AP32>=0.5%,-(AO32*10%),0) -> 0 | AR32: 0 | AS32: =IF(AR32>0,-(AO32+AQ32),0) -> 0 | AT32: =SUM(AS32,AQ32,AO32) -> 551250 | AU32: =AT32*70% -> 385875 | AV32: =AT32*30% -> 165375
B33: TOTAL PENCAPAIAN AREA JAWA TENGAH | C33: ='Pencapaian Sales Value'!G147 -> 0.70096802 | D33: ='Pencapaian Product Focus'!H147 -> 0.98188202 | E33: ='Pencapaian Product Focus'!L147 -> 0.59760479 | F33: ='Pencapaian Effective Call'!G147 -> 0.80128617 | G33: ='Pencapaian New Open Outlet'!G147 -> 0.43548387 | H33: ='Pencapaian Active Outlet'!G147 -> 0.71034483 | N33: =SUM(N28:N32) -> 3572250 | R33: ANWAR SIDIK | S33: SPV | T33: ='Pencapaian Sales Value'!G33 -> 1.0046479 | U33: ='Pencapaian Sales Value'!I33 -> 480000 | V33: ='Pencapaian Product Focus'!H33 -> 1.0950658 | W33: ='Pencapaian Product Focus'!L33 -> 0.96428571 | X33: ='Pencapaian Product Focus'!N33 -> 204000 | Y33: ='Pencapaian Effective Call'!G33 -> 0.91255814 | Z33: ='Pencapaian Effective Call'!I33 -> 0 | AA33: ='Pencapaian New Open Outlet'!G33 -> 1.35 | AB33: ='Pencapaian New Open Outlet'!I33 -> 336000 | AC33: ='Pencapaian Active Outlet'!G33 -> 1.0622318 | AD33: ='Pencapaian Active Outlet'!I33 -> 240000 | AE33: ='Pencapaian Item per Outlet'!G33 -> 0 | AF33: ='Pencapaian Item per Outlet'!I33 -> 0 | AG33: ='Pencapaian Product Display'!G33 -> 0 | AH33: ='Pencapaian Product Display'!I33 -> 0 | AI33: ='Pencapaian Sales Contract'!G33 -> 0 | AJ33: ='Pencapaian Sales Contract'!I33 -> 0 | AK33: ='Pencapaian Co-Branding'!G33 -> 0 | AL33: ='Pencapaian Co-Branding'!I33 -> 0 | AM33: ='Pencapaian Join Event Activity'!G33 -> 0 | AN33: ='Pencapaian Join Event Activity'!I33 -> 0 | AO33: =SUM(AN33,AL33,AJ33,AH33,AF33,AD33,AB33,Z33,X33,U33) -> 1260000 | AP33: 0 | AQ33: =IF(AP33>=0.5%,-(AO33*10%),0) -> 0 | AR33: 0 | AS33: =IF(AR33>0,-(AO33+AQ33),0) -> 0 | AT33: =SUM(AS33,AQ33,AO33) -> 1260000 | AU33: =AT33 -> 1260000 | AV33: 0
R34: TOTAL CABANG SUBANG | T34: ='Pencapaian Sales Value'!G34 -> 1.0046479 | U34: ='Pencapaian Sales Value'!I34 -> 1755000 | V34: ='Pencapaian Product Focus'!H34 -> 1.0950658 | W34: ='Pencapaian Product Focus'!L34 -> 0.96428571 | X34: ='Pencapaian Product Focus'!N34 -> 759000 | Y34: ='Pencapaian Effective Call'!G34 -> 0.91255814 | Z34: ='Pencapaian Effective Call'!I34 -> 281250 | AA34: ='Pencapaian New Open Outlet'!G34 -> 1.35 | AB34: ='Pencapaian New Open Outlet'!I34 -> 898500 | AC34: ='Pencapaian Active Outlet'!G34 -> 1.0622318 | AD34: ='Pencapaian Active Outlet'!I34 -> 240000 | AE34: ='Pencapaian Item per Outlet'!G34 -> 0 | AF34: ='Pencapaian Item per Outlet'!I34 -> 0 | AG34: ='Pencapaian Product Display'!G34 -> 0 | AH34: ='Pencapaian Product Display'!I34 -> 0 | AI34: ='Pencapaian Sales Contract'!G34 -> 0 | AJ34: ='Pencapaian Sales Contract'!I34 -> 0 | AK34: ='Pencapaian Co-Branding'!G34 -> 0 | AL34: ='Pencapaian Co-Branding'!I34 -> 0 | AM34: ='Pencapaian Join Event Activity'!G34 -> 0 | AN34: ='Pencapaian Join Event Activity'!I34 -> 0 | AO34: =SUM(AN34,AL34,AJ34,AH34,AF34,AD34,AB34,Z34,X34,U34) -> 3933750 | AP34: 0 | AQ34: =SUM(AQ29:AQ33) -> 0 | AR34: 0 | AS34: =SUM(AS29:AS33) -> 0 | AT34: =SUM(AS34,AQ34,AO34) -> 3933750 | AU34: =SUM(AU29:AU33) -> 2944875 | AV34: =SUM(AV29:AV33) -> 988875
B35: PENCAPAIAN AREA JAWA TIMUR | P35: PURWAKARTA | Q35: PWK-SLS-GT-001 | R35: Dede Supriadi | S35: 3 Orang | T35: ='Pencapaian Sales Value'!G35 -> 0.96998172 | U35: ='Pencapaian Sales Value'!I35 -> 450000 | V35: ='Pencapaian Product Focus'!H35 -> 0 | W35: ='Pencapaian Product Focus'!L35 -> 0 | X35: ='Pencapaian Product Focus'!N35 -> 0 | Y35: ='Pencapaian Effective Call'!G35 -> 0.97666667 | Z35: ='Pencapaian Effective Call'!I35 -> 180000 | AA35: ='Pencapaian New Open Outlet'!G35 -> 0 | AB35: ='Pencapaian New Open Outlet'!I35 -> 0 | AC35: ='Pencapaian Active Outlet'!G35 -> 1.0666667 | AD35: ='Pencapaian Active Outlet'!I35 -> 120000 | AE35: ='Pencapaian Item per Outlet'!G35 -> 0 | AF35: ='Pencapaian Item per Outlet'!I35 -> 0 | AG35: ='Pencapaian Product Display'!G35 -> 0 | AH35: ='Pencapaian Product Display'!I35 -> 0 | AI35: ='Pencapaian Sales Contract'!G35 -> 0 | AJ35: ='Pencapaian Sales Contract'!I35 -> 0 | AK35: ='Pencapaian Co-Branding'!G35 -> 0 | AL35: ='Pencapaian Co-Branding'!I35 -> 0 | AM35: ='Pencapaian Join Event Activity'!G35 -> 0 | AN35: ='Pencapaian Join Event Activity'!I35 -> 0 | AO35: =SUM(AN35,AL35,AJ35,AH35,AF35,AD35,AB35,Z35,X35,U35) -> 750000 | AP35: 0 | AQ35: =IF(AP35>=0.5%,-(AO35*10%),0) -> 0 | AR35: 0 | AS35: =IF(AR35>0,-(AO35+AQ35),0) -> 0 | AT35: =SUM(AS35,AQ35,AO35) -> 750000 | AU35: =AT35*55% -> 412500 | AV35: =AT35*45% -> 337500
B36: NAMA CABANG | C36: SALES VALUE | D36: PRODUCT FOCUS | F36: EFFECTIVE CALL | G36: NEW OPEN OUTLET | H36: ACTIVE OUTLET | I36: ITEM PER OUTLET | J36: PRODUCT DISPLAY | K36: SALES CONTRACT | L36: CO-BRANDING | M36: JOIN EVENT ACTIVITY | N36: TOTAL INSENTIF | Q36: PWK-SLS-GT-002 | R36: Yayan Nurjaman | S36: 2 Orang | T36: ='Pencapaian Sales Value'!G36 -> 0.99833741 | U36: ='Pencapaian Sales Value'!I36 -> 337500 | V36: ='Pencapaian Product Focus'!H36 -> 0 | W36: ='Pencapaian Product Focus'!L36 -> 0 | X36: ='Pencapaian Product Focus'!N36 -> 0 | Y36: ='Pencapaian Effective Call'!G36 -> 1.0285714 | Z36: ='Pencapaian Effective Call'!I36 -> 180000 | AA36: ='Pencapaian New Open Outlet'!G36 -> 0.2 | AB36: ='Pencapaian New Open Outlet'!I36 -> 0 | AC36: ='Pencapaian Active Outlet'!G36 -> 1.1363636 | AD36: ='Pencapaian Active Outlet'!I36 -> 112500 | AE36: ='Pencapaian Item per Outlet'!G36 -> 0 | AF36: ='Pencapaian Item per Outlet'!I36 -> 0 | AG36: ='Pencapaian Product Display'!G36 -> 0 | AH36: ='Pencapaian Product Display'!I36 -> 0 | AI36: ='Pencapaian Sales Contract'!G36 -> 0 | AJ36: ='Pencapaian Sales Contract'!I36 -> 0 | AK36: ='Pencapaian Co-Branding'!G36 -> 0 | AL36: ='Pencapaian Co-Branding'!I36 -> 0 | AM36: ='Pencapaian Join Event Activity'!G36 -> 0 | AN36: ='Pencapaian Join Event Activity'!I36 -> 0 | AO36: =SUM(AN36,AL36,AJ36,AH36,AF36,AD36,AB36,Z36,X36,U36) -> 630000 | AP36: 0 | AQ36: =IF(AP36>=0.5%,-(AO36*10%),0) -> 0 | AR36: 0 | AS36: =IF(AR36>0,-(AO36+AQ36),0) -> 0 | AT36: =SUM(AS36,AQ36,AO36) -> 630000 | AU36: =AT36*70% -> 441000 | AV36: =AT36*30% -> 189000
D37: VOLUME | E37: RO | Q37: PWK-SLS-GT-003 | R37: Acep Hendra | S37: 2 Orang | T37: ='Pencapaian Sales Value'!G37 -> 0.80220533 | U37: ='Pencapaian Sales Value'!I37 -> 225000 | V37: ='Pencapaian Product Focus'!H37 -> 0 | W37: ='Pencapaian Product Focus'!L37 -> 0 | X37: ='Pencapaian Product Focus'!N37 -> 0 | Y37: ='Pencapaian Effective Call'!G37 -> 0.70384615 | Z37: ='Pencapaian Effective Call'!I37 -> 45000 | AA37: ='Pencapaian New Open Outlet'!G37 -> 0.2 | AB37: ='Pencapaian New Open Outlet'!I37 -> 0 | AC37: ='Pencapaian Active Outlet'!G37 -> 1.1111111 | AD37: ='Pencapaian Active Outlet'!I37 -> 112500 | AE37: ='Pencapaian Item per Outlet'!G37 -> 0 | AF37: ='Pencapaian Item per Outlet'!I37 -> 0 | AG37: ='Pencapaian Product Display'!G37 -> 0 | AH37: ='Pencapaian Product Display'!I37 -> 0 | AI37: ='Pencapaian Sales Contract'!G37 -> 0 | AJ37: ='Pencapaian Sales Contract'!I37 -> 0 | AK37: ='Pencapaian Co-Branding'!G37 -> 0 | AL37: ='Pencapaian Co-Branding'!I37 -> 0 | AM37: ='Pencapaian Join Event Activity'!G37 -> 0 | AN37: ='Pencapaian Join Event Activity'!I37 -> 0 | AO37: =SUM(AN37,AL37,AJ37,AH37,AF37,AD37,AB37,Z37,X37,U37) -> 382500 | AP37: 0 | AQ37: =IF(AP37>=0.5%,-(AO37*10%),0) -> 0 | AR37: 0 | AS37: =IF(AR37>0,-(AO37+AQ37),0) -> 0 | AT37: =SUM(AS37,AQ37,AO37) -> 382500 | AU37: =AT37*70% -> 267750 | AV37: =AT37*30% -> 114750
B38: CABANG BANYUWANGI | C38: ='Pencapaian Sales Value'!G165 -> 0.99046015 | H38: ='Pencapaian Active Outlet'!G165 -> 1.1282051 | N38: =AO165 -> 2969000 | R38: ENDANG KUSBINI | S38: SPV | T38: ='Pencapaian Sales Value'!G38 -> 0.95821433 | U38: ='Pencapaian Sales Value'!I38 -> 336000 | V38: ='Pencapaian Product Focus'!H38 -> 0 | W38: ='Pencapaian Product Focus'!L38 -> 0 | X38: ='Pencapaian Product Focus'!N38 -> 0 | Y38: ='Pencapaian Effective Call'!G38 -> 0.91868132 | Z38: ='Pencapaian Effective Call'!I38 -> 168000 | AA38: ='Pencapaian New Open Outlet'!G38 -> 0.14285714 | AB38: ='Pencapaian New Open Outlet'!I38 -> 0 | AC38: ='Pencapaian Active Outlet'!G38 -> 1.104918 | AD38: ='Pencapaian Active Outlet'!I38 -> 336000 | AE38: ='Pencapaian Item per Outlet'!G38 -> 0 | AF38: ='Pencapaian Item per Outlet'!I38 -> 0 | AG38: ='Pencapaian Product Display'!G38 -> 0 | AH38: ='Pencapaian Product Display'!I38 -> 0 | AI38: ='Pencapaian Sales Contract'!G38 -> 0 | AJ38: ='Pencapaian Sales Contract'!I38 -> 0 | AK38: ='Pencapaian Co-Branding'!G38 -> 0 | AL38: ='Pencapaian Co-Branding'!I38 -> 0 | AM38: ='Pencapaian Join Event Activity'!G38 -> 0 | AN38: ='Pencapaian Join Event Activity'!I38 -> 0 | AO38: =SUM(AN38,AL38,AJ38,AH38,AF38,AD38,AB38,Z38,X38,U38) -> 840000 | AP38: 0 | AQ38: =IF(AP38>=0.5%,-(AO38*10%),0) -> 0 | AR38: 0 | AS38: =IF(AR38>0,-(AO38+AQ38),0) -> 0 | AT38: =SUM(AS38,AQ38,AO38) -> 840000 | AU38: =AT38 -> 840000 | AV38: 0
B39: CABANG JEMBER - SITUBONDO | C39: ='Pencapaian Sales Value'!G181 -> 0.71644363 | H39: ='Pencapaian Active Outlet'!G181 -> 0.4 | N39: =AO181 -> 450000 | R39: TOTAL CABANG PURWAKARTA | T39: ='Pencapaian Sales Value'!G39 -> 0.95821433 | U39: ='Pencapaian Sales Value'!I39 -> 1348500 | V39: ='Pencapaian Product Focus'!H39 -> 0 | W39: ='Pencapaian Product Focus'!L39 -> 0 | X39: ='Pencapaian Product Focus'!N39 -> 0 | Y39: ='Pencapaian Effective Call'!G39 -> 0.91868132 | Z39: ='Pencapaian Effective Call'!I39 -> 573000 | AA39: ='Pencapaian New Open Outlet'!G39 -> 0.14285714 | AB39: ='Pencapaian New Open Outlet'!I39 -> 0 | AC39: ='Pencapaian Active Outlet'!G39 -> 1.104918 | AD39: ='Pencapaian Active Outlet'!I39 -> 681000 | AE39: ='Pencapaian Item per Outlet'!G39 -> 0 | AF39: ='Pencapaian Item per Outlet'!I39 -> 0 | AG39: ='Pencapaian Product Display'!G39 -> 0 | AH39: ='Pencapaian Product Display'!I39 -> 0 | AI39: ='Pencapaian Sales Contract'!G39 -> 0 | AJ39: ='Pencapaian Sales Contract'!I39 -> 0 | AK39: ='Pencapaian Co-Branding'!G39 -> 0 | AL39: ='Pencapaian Co-Branding'!I39 -> 0 | AM39: ='Pencapaian Join Event Activity'!G39 -> 0 | AN39: ='Pencapaian Join Event Activity'!I39 -> 0 | AO39: =SUM(AN39,AL39,AJ39,AH39,AF39,AD39,AB39,Z39,X39,U39) -> 2602500 | AP39: 0 | AQ39: =SUM(AQ35:AQ38) -> 0 | AR39: 0 | AS39: =SUM(AS35:AS38) -> 0 | AT39: =SUM(AS39,AQ39,AO39) -> 2602500 | AU39: =SUM(AU35:AU38) -> 1961250 | AV39: =SUM(AV35:AV38) -> 641250
B40: CABANG PROBOLINGGO - PASURUAN | C40: ='Pencapaian Sales Value'!G199 -> 0.76989445 | H40: ='Pencapaian Active Outlet'!G199 -> 0.66352941 | N40: =AO199 -> 1173000 | R40: TOTAL AREA JAWA BARAT-1 | T40: ='Pencapaian Sales Value'!G40 -> 0.89525819 | U40: ='Pencapaian Sales Value'!I40 -> 9278000 | V40: ='Pencapaian Product Focus'!H40 -> 0.93931294 | W40: ='Pencapaian Product Focus'!L40 -> 0.98344574 | X40: ='Pencapaian Product Focus'!N40 -> 3607000 | Y40: ='Pencapaian Effective Call'!G40 -> 0.92789788 | Z40: ='Pencapaian Effective Call'!I40 -> 2405250 | AA40: ='Pencapaian New Open Outlet'!G40 -> 0.37654321 | AB40: ='Pencapaian New Open Outlet'!I40 -> 1048500 | AC40: ='Pencapaian Active Outlet'!G40 -> 0.98463256 | AD40: ='Pencapaian Active Outlet'!I40 -> 1430000 | AE40: ='Pencapaian Item per Outlet'!G40 -> 0.79537525 | AF40: ='Pencapaian Item per Outlet'!I40 -> 1626000 | AG40: ='Pencapaian Product Display'!G40 -> 0.89090909 | AH40: ='Pencapaian Product Display'!I40 -> 40000 | AI40: ='Pencapaian Sales Contract'!G40 -> 0 | AJ40: ='Pencapaian Sales Contract'!I40 -> 0 | AK40: ='Pencapaian Co-Branding'!G40 -> 0 | AL40: ='Pencapaian Co-Branding'!I40 -> 0 | AM40: ='Pencapaian Join Event Activity'!G40 -> 1 | AN40: ='Pencapaian Join Event Activity'!I40 -> 50000 | AO40: =SUM(AN40,AL40,AJ40,AH40,AF40,AD40,AB40,Z40,X40,U40) -> 19484750 | AP40: 0.0091240407 | AQ40: =SUM(AQ39,AQ34,AQ28) -> -287750 | AR40: 8.4008463e-05 | AS40: =SUM(AS39,AS34,AS28) -> -1605000 | AT40: =SUM(AS40,AQ40,AO40) -> 17592000 | AU40: =SUM(AU39,AU34,AU28) -> 11771250 | AV40: =SUM(AV39,AV34,AV28) -> 5820750
B41: CABANG MALANG UTARA - MALANG SELATAN | C41: ='Pencapaian Sales Value'!G215 -> 0.4777687 | H41: ='Pencapaian Active Outlet'!G215 -> 0.3037037 | N41: =AO215 -> 390000 | P41: Pencairan ASM | Q41: skema All Prod & Value kolom diatas | BC41: *AR MT tetap muncul, tapi di sheet 'Pencairan' dikeluarkan dari pengurang insentif
...

Sheet Rekap Insentif ASM
B2: LAMPIRAN INSENTIF ASM
B4: AREA | C4: NAMA ASM | D4: TYPE SALES | E4: SALES VALUE | G4: ACTIVE OUTLET | I4: TOTAL | J4: AR PERFORM | N4: TOTAL INSENTIF DITERIMA
E5: PENCAPAIAN | F5: INSENTIF | G5: PENCAPAIAN | H5: INSENTIF | J5: OVERDUE (>30 HARI) | K5: PENGURANG INSENTIF | L5: BAD DEBT | M5: PENGURANG INSENTIF
B6: ='Pencapaian ASM'!B7 -> JABAR-1 | C6: ='Pencapaian ASM'!C7 -> BENNY HERDIANA | D6: ='Pencapaian ASM'!G7 -> ASM | E6: ='Pencapaian ASM'!F7 -> 0.89525819 | F6: ='Pencapaian ASM'!H7 -> 472500 | G6: ='Pencapaian ASM'!F26 -> 0.98463256 | H6: ='Pencapaian ASM'!H26 -> 315000 | I6: =SUM(H6,F6) -> 787500 | J6: ='Rekap Insentif Sales'!AP40 -> 0.0091240407 | K6: =IF(J6>=0.5%,-I6*20%,0) -> -157500 | L6: ='Rekap Insentif Sales'!AR40 -> 8.4008463e-05 | M6: =IF(L6>0,-(I6+K6),0) -> -630000 | N6: =I6+K6+M6 -> 0
B7: ='Pencapaian ASM'!B8 -> JABAR-2 | C7: ='Pencapaian ASM'!C8 -> ARIS JOHAR | D7: ='Pencapaian ASM'!G8 -> ASM | E7: ='Pencapaian ASM'!F8 -> 0.82895215 | F7: ='Pencapaian ASM'!H8 -> 472500 | G7: ='Pencapaian ASM'!F27 -> 0.89526293 | H7: ='Pencapaian ASM'!H27 -> 202500 | I7: =SUM(H7,F7) -> 675000 | J7: ='Rekap Insentif Sales'!AP77 -> 0.005327445 | K7: =IF(J7>=0.5%,-I7*20%,0) -> -135000 | L7: ='Rekap Insentif Sales'!AR77 -> 0.0022532301 | M7: =IF(L7>0,-(I7+K7),0) -> -540000 | N7: =I7+K7+M7 -> 0
B8: ='Pencapaian ASM'!B9 -> JABAR-3 | C8: ='Pencapaian ASM'!C9 -> ANDREAS PREMADYA | D8: ='Pencapaian ASM'!G9 -> ASM | E8: ='Pencapaian ASM'!F9 -> 0.71673365 | F8: ='Pencapaian ASM'!H9 -> 262500 | G8: ='Pencapaian ASM'!F28 -> 0.88888889 | H8: ='Pencapaian ASM'!H28 -> 202500 | I8: =SUM(H8,F8) -> 465000 | J8: ='Rekap Insentif Sales'!AP95 -> 0.0021331853 | K8: =IF(J8>=0.5%,-I8*20%,0) -> 0 | L8: ='Rekap Insentif Sales'!AR95 -> 0 | M8: =IF(L8>0,-(I8+K8),0) -> 0 | N8: =I8+K8+M8 -> 465000
B9: ='Pencapaian ASM'!B10 -> JATENG | C9: ='Pencapaian ASM'!C10 -> UUT KURNIAWAN | D9: ='Pencapaian ASM'!G10 -> ASM | E9: ='Pencapaian ASM'!F10 -> 0.70096802 | F9: ='Pencapaian ASM'!H10 -> 262500 | G9: ='Pencapaian ASM'!F29 -> 0.71034483 | H9: ='Pencapaian ASM'!H29 -> 112500 | I9: =SUM(H9,F9) -> 375000 | J9: ='Rekap Insentif Sales'!AP147 -> 0.0025767704 | K9: =IF(J9>=0.5%,-I9*20%,0) -> 0 | L9: ='Rekap Insentif Sales'!AR147 -> 0.0014758135 | M9: =IF(L9>0,-(I9+K9),0) -> -375000 | N9: =I9+K9+M9 -> 0
